Workbook

Sheet 使用说明
B2: 护理推送平台 · 功能勾选表
B3: 先 SaaS 上线测试，后做小程序。请只改「功能勾选」表中的黄色「勾选」列，汇总会自动重算。
B5: 怎么勾
B6: 1 | C6: 打开「功能勾选」工作表 | D6: 每条功能一行。黄色「勾选」列已按建议测试包预填，可直接改。
B7: 2 | C7: 用下拉选择，不要手打 | D7: 只能选：纳入 / 延期 / 不做。点单元格右侧箭头。
B8: 3 | C8: 三种选项的含义 | D8: 纳入 = 进入本期 SaaS 测试开发；延期 = 小程序或二期再做；不做 = 明确砍掉。
B9: 4 | C9: 对照「建议勾选」 | D9: 灰色列是目录建议，不要改。若你改了黄色列，「是否改建议」会显示「已改」。
B10: 5 | C10: 看「勾选汇总」 | D10: 纳入/延期/不做的条数和按模块拆分会随你的勾选变化。把本文件发回即可。
B11: 6 | C11: 恢复默认建议 | D11: 若改乱：把「建议勾选」整列复制，选择性粘贴到「勾选」列（只粘贴值）。
B13: 颜色
B14: 纳入 | C14: 延期 | D14: 不做 | E14: 黄色单元格 = 请你改
B16: 建议测试包（预填为「纳入」）能演示：护士长建路径 → 责任护士套到床位 → 患者扫床头码或打开 H5 → 未读进入护士待办 → 护理部看覆盖率。直播、患友会、培训考试、HIS、服务号、秀米、签字板、AI 问答默认不是「纳入」。

Sheet 功能勾选
A1: 护理推送平台功能目录（请在黄色「勾选」列下拉选择）
A2: 勾选只能是：纳入（本期 SaaS 做） / 延期（小程序或二期） / 不做（砍掉）。灰色「建议勾选」是目录建议，已复制到黄色列作为起点。筛选可按模块、建议标签过滤。
A4: 勾选 | B4: 编号 | C4: 模块 | D4: 功能 | E4: 说明 | F4: 建议标签 | G4: 建议勾选 | H4: 是否改建议 | I4: 主要角色 | J4: 备注
A5: 纳入 | B5: 01.1 | C5: 01 组织账号与权限 | D5: 医院 / 院区 / 科室 / 病区树 | E5: 多租户隔离；宣武可先单院单科，模型不能写死成一个科室。 | F5: SaaS-P0 | G5: 纳入 | H5: =IF(A5="","未勾选",IF(A5=G5,"一致","已改")) -> 一致 | I5: 护理部
A6: 纳入 | B6: 01.2 | C6: 01 组织账号与权限 | D6: 角色：护理部、护士长、责任护士、只读质控 | E6: 责任护士默认只看自己的床，这是和全科医护工具的分界。 | F6: SaaS-P0 | G6: 纳入 | H6: =IF(A6="","未勾选",IF(A6=G6,"一致","已改")) -> 一致 | I6: 护理部、护士长
A7: 纳入 | B7: 01.3 | C7: 01 组织账号与权限 | D7: 手机号 + 密码 / 验证码登录 | E7: SaaS 测试入口。微信登录请另见本行备注，属小程序期。 | F7: SaaS-P0 | G7: 纳入 | H7: =IF(A7="","未勾选",IF(A7=G7,"一致","已改")) -> 一致 | I7: 全部医护 | J7: 微信登录标为 MP-P0，请用「延期」表达小程序再做，或另开一行备注。
A8: 纳入 | B8: 01.4 | C8: 01 组织账号与权限 | D8: 科室二维码邀请医护加入 | E8: 扫码注册加入科室团队。 | F8: SaaS-P1 / MP-P0 | G8: 延期 | H8: =IF(A8="","未勾选",IF(A8=G8,"一致","已改")) -> 已改 | I8: 护士长 | J8: 小程序期几乎必做。
A9: 不做 | B9: 01.5 | C9: 01 组织账号与权限 | D9: 护士层级（N0–N5 等） | E9: 仅当要做培训考试时需要。 | F9: 后置 | G9: 不做 | H9: =IF(A9="","未勾选",IF(A9=G9,"一致","已改")) -> 一致 | I9: 护理部 | J9: 不要为推送 MVP 建层级。
A10: 不做 | B10: 01.6 | C10: 01 组织账号与权限 | D10: 多医院切换（SaaS 运营后台） | E10: 运营侧切换租户/医院。 | F10: SaaS-P1 | G10: 延期 | H10: =IF(A10="","未勾选",IF(A10=G10,"一致","已改")) -> 已改 | I10: 系统管理员 | J10: 仅当要多院试点再纳入。
A11: 纳入 | B11: 02.1 | C11: 02 患者、床位、入组 | D11: 床位图 / 床卡列表（病房样式） | E11: 护士站主界面。 | F11: SaaS-P0 | G11: 纳入 | H11: =IF(A11="","未勾选",IF(A11=G11,"一致","已改")) -> 一致 | I11: 护士长、责任护士
A12: 延期 | B12: 02.2 | C12: 02 患者、床位、入组 | D12: 非病房名单（门诊、日间、检查、手术室） | E12: 扫码患者列表，非床位宫格。 | F12: SaaS-P1 | G12: 延期 | H12: =IF(A12="","未勾选",IF(A12=G12,"一致","已改")) -> 一致 | I12: 护士长、责任护士 | J12: 试点含门诊再纳入。
A13: 纳入 | B13: 02.3 | C13: 02 患者、床位、入组 | D13: 患者档案：姓名、床号、入科时间、诊断/病种标签、联系人 | E13: 推送对象主数据。测试期可手建或 Excel 导入。 | F13: SaaS-P0 | G13: 纳入 | H13: =IF(A13="","未勾选",IF(A13=G13,"一致","已改")) -> 一致 | I13: 责任护士 | J13: 不必先接 HIS。
A14: 纳入 | B14: 02.4 | C14: 02 患者、床位、入组 | D14: 责任床位分配（护士长分床 / 护士领床） | E14: 没有分床就没有「我的患者」。 | F14: SaaS-P0 | G14: 纳入 | H14: =IF(A14="","未勾选",IF(A14=G14,"一致","已改")) -> 一致 | I14: 护士长、责任护士
A15: 纳入 | B15: 02.5 | C15: 02 患者、床位、入组 | D15: 标记组（病种、手术、高危跌倒、糖尿病饮食等） | E15: 供精准群发和智能计划圈人。 | F15: SaaS-P0 | G15: 纳入 | H15: =IF(A15="","未勾选",IF(A15=G15,"一致","已改")) -> 一致 | I15: 护士长、责任护士
A16: 纳入 | B16: 02.6 | C16: 02 患者、床位、入组 | D16: 床头宣教码、一床一码、扫码入科 | E16: 测试期患者主入口。 | F16: SaaS-P0 | G16: 纳入 | H16: =IF(A16="","未勾选",IF(A16=G16,"一致","已改")) -> 一致 | I16: 责任护士、患者
A17: 延期 | B17: 02.7 | C17: 02 患者、床位、入组 | D17: 扫码人数上限（患者+家属） | E17: 如填 2，床上已有 2 人则须先移出院。 | F17: SaaS-P1 | G17: 延期 | H17: =IF(A17="","未勾选",IF(A17=G17,"一致","已改")) -> 一致 | I17: 护士长
A18: 纳入 | B18: 02.8 | C18: 02 患者、床位、入组 | D18: 扫码后必填表单才进宣教中心 | E18: 开启后扫码必须填指定信息项。 | F18: SaaS-P1 | G18: 延期 | H18: =IF(A18="","未勾选",IF(A18=G18,"一致","已改")) -> 已改 | I18: 护士长、患者
A19: 纳入 | B19: 02.9 | C19: 02 患者、床位、入组 | D19: 转床、出院、自动出院（按扫码日或入院日） | E19: 任务和床位必须能结束。默认可按住院天数自动出院。 | F19: SaaS-P0 | G19: 纳入 | H19: =IF(A19="","未勾选",IF(A19=G19,"一致","已改")) -> 一致 | I19: 护士长、责任护士
A20: 延期 | B20: 02.10 | C20: 02 患者、床位、入组 | D20: 主联系人 / 家属单独策略 | E20: 例如家属单独收一份出院指导。 | F20: SaaS-P1 | G20: 延期 | H20: =IF(A20="","未勾选",IF(A20=G20,"一致","已改")) -> 一致 | I20: 责任护士、家属
A21: 不做 | B21: 02.11 | C21: 02 患者、床位、入组 | D21: HIS 同步患者、入出院、诊断 | E21: 材料写明定制开发。 | F21: 后置 | G21: 不做 | H21: =IF(A21="","未勾选",IF(A21=G21,"一致","已改")) -> 一致 | I21: 系统管理员 | J21: 测试用导入/手建。
A22: 纳入 | B22: 03.1 | C22: 03 内容知识库 | D22: 文章：标题、封面、正文、图文/音频/视频 | E22: 首期富文本即可，视频可外链或上传。 | F22: SaaS-P0 | G22: 纳入 | H22: =IF(A22="","未勾选",IF(A22=G22,"一致","已改")) -> 一致 | I22: 护士长、责任护士、内容运营 | J22: 不做秀米。
A23: 纳入 | B23: 03.2 | C23: 03 内容知识库 | D23: 科室分类树：入院、出院、检查、手术、疾病、护理、饮食、用药、康复 | E23: 对应宣教中心菜单。 | F23: SaaS-P0 | G23: 纳入 | H23: =IF(A23="","未勾选",IF(A23=G23,"一致","已改")) -> 一致 | I23: 护士长、患者
A24: 纳入 | B24: 03.3 | C24: 03 内容知识库 | D24: 疾病标签、关键词 | E24: 便于检索和按病种匹配。 | F24: SaaS-P1 | G24: 延期 | H24: =IF(A24="","未勾选",IF(A24=G24,"一致","已改")) -> 已改 | I24: 内容运营
A25: 纳入 | B25: 03.4 | C25: 03 内容知识库 | D25: 院内共享 / 仅本科室 | E25: 文章发布范围。 | F25: SaaS-P1 | G25: 延期 | H25: =IF(A25="","未勾选",IF(A25=G25,"一致","已改")) -> 已改 | I25: 护士长、护理部
A26: 不做 | B26: 03.5 | C26: 03 内容知识库 | D26: 文章绑定问卷（读完即测） | E26: 阅读完成后弹出关联问卷。 | F26: SaaS-P1 | G26: 延期 | H26: =IF(A26="","未勾选",IF(A26=G26,"一致","已改")) -> 已改 | I26: 护士长
A27: 纳入 | B27: 03.6 | C27: 03 内容知识库 | D27: 公共内容库 / 引用发布 | E27: 引用院内或其他来源后发布到本科。 | F27: SaaS-P1 | G27: 延期 | H27: =IF(A27="","未勾选",IF(A27=G27,"一致","已改")) -> 已改 | I27: 内容运营
A28: 不做 | B28: 03.7 | C28: 03 内容知识库 | D28: 秀米类可视化排版 | E28: 首期 Markdown/富文本足够。 | F28: 慎选 | G28: 不做 | H28: =IF(A28="","未勾选",IF(A28=G28,"一致","已改")) -> 一致 | I28: 内容运营 | J28: 运营很重。
A29: 纳入 | B29: 03.8 | C29: 03 内容知识库 | D29: 变更记录、预览、导出 PDF | E29: 内容留痕与线下打印。 | F29: SaaS-P1 | G29: 延期 | H29: =IF(A29="","未勾选",IF(A29=G29,"一致","已改")) -> 已改 | I29: 护士长、护理部
A30: 不做 | B30: 03.9 | C30: 03 内容知识库 | D30: 供应商代运营知识库工作台 | E30: 商务服务，不是开发核心。 | F30: 后置 | G30: 不做 | H30: =IF(A30="","未勾选",IF(A30=G30,"一致","已改")) -> 一致 | I30: 内容运营
A31: 纳入 | B31: 04.1 | C31: 04 宣教路径模板 | D31: 路径模板：入院第0/1天、术前1天、术后1天、出院当天、出院后第N天 | E31: 产品主轴，替代每人手配智能推送。 | F31: SaaS-P0 | G31: 纳入 | H31: =IF(A31="","未勾选",IF(A31=G31,"一致","已改")) -> 一致 | I31: 护理部、护士长
A32: 纳入 | B32: 04.2 | C32: 04 宣教路径模板 | D32: 病种路径：脑梗死、帕金森、导管维护、2型糖尿病等 | E32: 对照材料 HIS 计划样例。 | F32: SaaS-P1 | G32: 延期 | H32: =IF(A32="","未勾选",IF(A32=G32,"一致","已改")) -> 已改 | I32: 护理部、护士长 | J32: 按试点科室加。
A33: 纳入 | B33: 04.3 | C33: 04 宣教路径模板 | D33: 路径内条目：文章 / 问卷 / 通知 / 需当面补讲勾选 | E33: 一条路径里混合内容类型。 | F33: SaaS-P0 | G33: 纳入 | H33: =IF(A33="","未勾选",IF(A33=G33,"一致","已改")) -> 一致 | I33: 护理部、护士长
A34: 纳入 | B34: 04.4 | C34: 04 宣教路径模板 | D34: 护士长启用路径、责任护士一键套到患者 | E34: 从模板变成该患者的任务。 | F34: SaaS-P0 | G34: 纳入 | H34: =IF(A34="","未勾选",IF(A34=G34,"一致","已改")) -> 一致 | I34: 护士长、责任护士
A35: 纳入 | B35: 04.5 | C35: 04 宣教路径模板 | D35: 路径版本与审核（内容上线需护士长过） | E35: 模板变更走审核。 | F35: SaaS-P1 | G35: 延期 | H35: =IF(A35="","未勾选",IF(A35=G35,"一致","已改")) -> 已改 | I35: 护士长、护理部
A36: 纳入 | B36: 04.6 | C36: 04 宣教路径模板 | D36: 未读自动进入「需当面补讲」任务 | E36: 弥补推了但没看的护理风险。 | F36: SaaS-P1 | G36: 延期 | H36: =IF(A36="","未勾选",IF(A36=G36,"一致","已改")) -> 已改 | I36: 责任护士
A37: 纳入 | B37: 05.1 | C37: 05 手动推送 / 群发 | D37: 选内容 → 筛患者 → 立即发送 | E37: 可发文章、问卷、通知。 | F37: SaaS-P0 | G37: 纳入 | H37: =IF(A37="","未勾选",IF(A37=G37,"一致","已改")) -> 一致 | I37: 护士长、责任护士
A38: 纳入 | B38: 05.2 | C38: 05 手动推送 / 群发 | D38: 定时发送、失败/未读重发 | E38: 夜班或次日补推。 | F38: SaaS-P0 | G38: 纳入 | H38: =IF(A38="","未勾选",IF(A38=G38,"一致","已改")) -> 一致 | I38: 护士长、责任护士
A39: 纳入 | B39: 05.3 | C39: 05 手动推送 / 群发 | D39: 通知类型：图文、纯文本、语音、视频 | E39: 语音可再后置。 | F39: SaaS-P1 | G39: 延期 | H39: =IF(A39="","未勾选",IF(A39=G39,"一致","已改")) -> 已改 | I39: 责任护士
A40: 纳入 | B40: 05.4 | C40: 05 手动推送 / 群发 | D40: 发送人、时间、已读/应发人数留痕 | E40: 质控最小集。 | F40: SaaS-P0 | G40: 纳入 | H40: =IF(A40="","未勾选",IF(A40=G40,"一致","已改")) -> 一致 | I40: 护士长、护理部
A41: 纳入 | B41: 05.5 | C41: 05 手动推送 / 群发 | D41: 仅推责任床（默认）vs 推全科 | E41: 防误推。 | F41: SaaS-P0 | G41: 纳入 | H41: =IF(A41="","未勾选",IF(A41=G41,"一致","已改")) -> 一致 | I41: 责任护士、护士长
...

Sheet 勾选汇总
B2: 勾选汇总（改「功能勾选」黄色列后，这里会跟着变）
B4: 纳入 | C4: 延期 | D4: 不做 | E4: 未勾选 | F4: 功能总数
B5: =COUNTIF(功能勾选!$A$5:$A$104,"纳入") -> 59 | C5: =COUNTIF(功能勾选!$A$5:$A$104,"延期") -> 3 | D5: =COUNTIF(功能勾选!$A$5:$A$104,"不做") -> 38 | E5: =COUNTBLANK(功能勾选!$A$5:$A$104) -> 0 | F5: =COUNTA(功能勾选!$B$5:$B$104) -> 100
B6: 已改建议 | C6: 与建议一致 | D6: 纳入占总数
B7: =COUNTIF(功能勾选!$H$5:$H$104,"已改") -> 37 | C7: =COUNTIF(功能勾选!$H$5:$H$104,"一致") -> 63 | D7: =IF(F5=0,"-",B5/F5) -> 0.59
B9: 按模块 | H9: 按建议标签（看你勾成纳入的分布）
B10: 模块 | C10: 纳入 | D10: 延期 | E10: 不做 | F10: 小计 | H10: 建议标签含 | I10: 你勾选为纳入
B11: 01 组织账号与权限 | C11: =COUNTIFS(功能勾选!$C$5:$C$104,B11,功能勾选!$A$5:$A$104,"纳入") -> 4 | D11: =COUNTIFS(功能勾选!$C$5:$C$104,B11,功能勾选!$A$5:$A$104,"延期") -> 0 | E11: =COUNTIFS(功能勾选!$C$5:$C$104,B11,功能勾选!$A$5:$A$104,"不做") -> 2 | F11: =SUM(C11:E11) -> 6 | H11: SaaS-P0 | I11: =COUNTIFS(功能勾选!$F$5:$F$104,"*"&H11&"*",功能勾选!$A$5:$A$104,"纳入") -> 37
B12: 02 患者、床位、入组 | C12: =COUNTIFS(功能勾选!$C$5:$C$104,B12,功能勾选!$A$5:$A$104,"纳入") -> 7 | D12: =COUNTIFS(功能勾选!$C$5:$C$104,B12,功能勾选!$A$5:$A$104,"延期") -> 3 | E12: =COUNTIFS(功能勾选!$C$5:$C$104,B12,功能勾选!$A$5:$A$104,"不做") -> 1 | F12: =SUM(C12:E12) -> 11 | H12: SaaS-P1 | I12: =COUNTIFS(功能勾选!$F$5:$F$104,"*"&H12&"*",功能勾选!$A$5:$A$104,"纳入") -> 18
B13: 03 内容知识库 | C13: =COUNTIFS(功能勾选!$C$5:$C$104,B13,功能勾选!$A$5:$A$104,"纳入") -> 6 | D13: =COUNTIFS(功能勾选!$C$5:$C$104,B13,功能勾选!$A$5:$A$104,"延期") -> 0 | E13: =COUNTIFS(功能勾选!$C$5:$C$104,B13,功能勾选!$A$5:$A$104,"不做") -> 3 | F13: =SUM(C13:E13) -> 9 | H13: MP-P0 | I13: =COUNTIFS(功能勾选!$F$5:$F$104,"*"&H13&"*",功能勾选!$A$5:$A$104,"纳入") -> 4
B14: 04 宣教路径模板 | C14: =COUNTIFS(功能勾选!$C$5:$C$104,B14,功能勾选!$A$5:$A$104,"纳入") -> 6 | D14: =COUNTIFS(功能勾选!$C$5:$C$104,B14,功能勾选!$A$5:$A$104,"延期") -> 0 | E14: =COUNTIFS(功能勾选!$C$5:$C$104,B14,功能勾选!$A$5:$A$104,"不做") -> 0 | F14: =SUM(C14:E14) -> 6 | H14: MP-P1 | I14: =COUNTIFS(功能勾选!$F$5:$F$104,"*"&H14&"*",功能勾选!$A$5:$A$104,"纳入") -> 0
B15: 05 手动推送 / 群发 | C15: =COUNTIFS(功能勾选!$C$5:$C$104,B15,功能勾选!$A$5:$A$104,"纳入") -> 6 | D15: =COUNTIFS(功能勾选!$C$5:$C$104,B15,功能勾选!$A$5:$A$104,"延期") -> 0 | E15: =COUNTIFS(功能勾选!$C$5:$C$104,B15,功能勾选!$A$5:$A$104,"不做") -> 0 | F15: =SUM(C15:E15) -> 6 | H15: 后置 | I15: =COUNTIFS(功能勾选!$F$5:$F$104,"*"&H15&"*",功能勾选!$A$5:$A$104,"纳入") -> 2
B16: 06 智能 / 计划推送 | C16: =COUNTIFS(功能勾选!$C$5:$C$104,B16,功能勾选!$A$5:$A$104,"纳入") -> 3 | D16: =COUNTIFS(功能勾选!$C$5:$C$104,B16,功能勾选!$A$5:$A$104,"延期") -> 0 | E16: =COUNTIFS(功能勾选!$C$5:$C$104,B16,功能勾选!$A$5:$A$104,"不做") -> 2 | F16: =SUM(C16:E16) -> 5 | H16: 慎选 | I16: =COUNTIFS(功能勾选!$F$5:$F$104,"*"&H16&"*",功能勾选!$A$5:$A$104,"纳入") -> 0
B17: 07 触达渠道 | C17: =COUNTIFS(功能勾选!$C$5:$C$104,B17,功能勾选!$A$5:$A$104,"纳入") -> 4 | D17: =COUNTIFS(功能勾选!$C$5:$C$104,B17,功能勾选!$A$5:$A$104,"延期") -> 0 | E17: =COUNTIFS(功能勾选!$C$5:$C$104,B17,功能勾选!$A$5:$A$104,"不做") -> 4 | F17: =SUM(C17:E17) -> 8
B18: 08 阅读闭环与护理任务 | C18: =COUNTIFS(功能勾选!$C$5:$C$104,B18,功能勾选!$A$5:$A$104,"纳入") -> 3 | D18: =COUNTIFS(功能勾选!$C$5:$C$104,B18,功能勾选!$A$5:$A$104,"延期") -> 0 | E18: =COUNTIFS(功能勾选!$C$5:$C$104,B18,功能勾选!$A$5:$A$104,"不做") -> 4 | F18: =SUM(C18:E18) -> 7 | H18: 把本文件填完后发回即可。黄色列改完，「纳入」清单就是下一期开发范围。若某条建议标签含多项（如 SaaS-P1 / MP-P0），右侧统计可能重复计数，仅作参考；以「按模块」和顶部四格为准。
B19: 09 问卷 | C19: =COUNTIFS(功能勾选!$C$5:$C$104,B19,功能勾选!$A$5:$A$104,"纳入") -> 5 | D19: =COUNTIFS(功能勾选!$C$5:$C$104,B19,功能勾选!$A$5:$A$104,"延期") -> 0 | E19: =COUNTIFS(功能勾选!$C$5:$C$104,B19,功能勾选!$A$5:$A$104,"不做") -> 2 | F19: =SUM(C19:E19) -> 7
B20: 10 咨询与消息 | C20: =COUNTIFS(功能勾选!$C$5:$C$104,B20,功能勾选!$A$5:$A$104,"纳入") -> 0 | D20: =COUNTIFS(功能勾选!$C$5:$C$104,B20,功能勾选!$A$5:$A$104,"延期") -> 0 | E20: =COUNTIFS(功能勾选!$C$5:$C$104,B20,功能勾选!$A$5:$A$104,"不做") -> 6 | F20: =SUM(C20:E20) -> 6
B21: 11 患者端宣教中心 | C21: =COUNTIFS(功能勾选!$C$5:$C$104,B21,功能勾选!$A$5:$A$104,"纳入") -> 3 | D21: =COUNTIFS(功能勾选!$C$5:$C$104,B21,功能勾选!$A$5:$A$104,"延期") -> 0 | E21: =COUNTIFS(功能勾选!$C$5:$C$104,B21,功能勾选!$A$5:$A$104,"不做") -> 2 | F21: =SUM(C21:E21) -> 5
B22: 12 护理质控与成果 | C22: =COUNTIFS(功能勾选!$C$5:$C$104,B22,功能勾选!$A$5:$A$104,"纳入") -> 5 | D22: =COUNTIFS(功能勾选!$C$5:$C$104,B22,功能勾选!$A$5:$A$104,"延期") -> 0 | E22: =COUNTIFS(功能勾选!$C$5:$C$104,B22,功能勾选!$A$5:$A$104,"不做") -> 1 | F22: =SUM(C22:E22) -> 6
B23: 13 团队、通知、反馈 | C23: =COUNTIFS(功能勾选!$C$5:$C$104,B23,功能勾选!$A$5:$A$104,"纳入") -> 2 | D23: =COUNTIFS(功能勾选!$C$5:$C$104,B23,功能勾选!$A$5:$A$104,"延期") -> 0 | E23: =COUNTIFS(功能勾选!$C$5:$C$104,B23,功能勾选!$A$5:$A$104,"不做") -> 1 | F23: =SUM(C23:E23) -> 3
B24: 14 患友会 / 直播 / 讲堂 | C24: =COUNTIFS(功能勾选!$C$5:$C$104,B24,功能勾选!$A$5:$A$104,"纳入") -> 0 | D24: =COUNTIFS(功能勾选!$C$5:$C$104,B24,功能勾选!$A$5:$A$104,"延期") -> 0 | E24: =COUNTIFS(功能勾选!$C$5:$C$104,B24,功能勾选!$A$5:$A$104,"不做") -> 3 | F24: =SUM(C24:E24) -> 3
B25: 15 医护培训与考试 | C25: =COUNTIFS(功能勾选!$C$5:$C$104,B25,功能勾选!$A$5:$A$104,"纳入") -> 1 | D25: =COUNTIFS(功能勾选!$C$5:$C$104,B25,功能勾选!$A$5:$A$104,"延期") -> 0 | E25: =COUNTIFS(功能勾选!$C$5:$C$104,B25,功能勾选!$A$5:$A$104,"不做") -> 1 | F25: =SUM(C25:E25) -> 2
B26: 16 集成与安全 | C26: =COUNTIFS(功能勾选!$C$5:$C$104,B26,功能勾选!$A$5:$A$104,"纳入") -> 4 | D26: =COUNTIFS(功能勾选!$C$5:$C$104,B26,功能勾选!$A$5:$A$104,"延期") -> 0 | E26: =COUNTIFS(功能勾选!$C$5:$C$104,B26,功能勾选!$A$5:$A$104,"不做") -> 2 | F26: =SUM(C26:E26) -> 6
B27: 17 AI 增强 | C27: =COUNTIFS(功能勾选!$C$5:$C$104,B27,功能勾选!$A$5:$A$104,"纳入") -> 0 | D27: =COUNTIFS(功能勾选!$C$5:$C$104,B27,功能勾选!$A$5:$A$104,"延期") -> 0 | E27: =COUNTIFS(功能勾选!$C$5:$C$104,B27,功能勾选!$A$5:$A$104,"不做") -> 4 | F27: =SUM(C27:E27) -> 4
B28: 合计 | C28: =SUM(C11:C27) -> 59 | D28: =SUM(D11:D27) -> 3 | E28: =SUM(E11:E27) -> 38 | F28: =SUM(F11:F27) -> 100
B30: 校验
B31: 模块小计是否等于功能总数 | C31: =IF(F28=F5,"通过","不通过") -> 通过
B32: 纳入+延期+不做+未勾选 是否等于总数 | C32: =IF(B5+C5+D5+E5=F5,"通过","不通过") -> 通过
